---
title: Hantera fel i varaktiga funktioner – Azure
description: Lär dig mer om att hantera fel i tillägget varaktiga funktioner för Azure Functions.
services: functions
author: ggailey777
manager: jeconnoc
keywords: ''
ms.service: azure-functions
ms.devlang: multiple
ms.topic: conceptual
ms.date: 12/07/2018
ms.author: azfuncdf
ms.openlocfilehash: 79af90d1c2c5b698ee7394f7fb20486b3069038c
ms.sourcegitcommit: 45e4466eac6cfd6a30da9facd8fe6afba64f6f50
ms.translationtype: MT
ms.contentlocale: sv-SE
ms.lasthandoff: 06/07/2019
ms.locfileid: "66751941"
---
# <a name="handling-errors-in-durable-functions-azure-functions"></a>Hantera fel i varaktiga funktioner (Azure Functions)

Hållbar funktionen orkestreringar implementeras i kod och kan använda funktionerna för hantering av fel i programmeringsspråket. Med detta i åtanke, det verkligen inte finns några nya begrepp som du behöver lära dig om hur du använder felhantering och ersättning till din orkestreringar. Det finns dock några beteenden som du bör känna till.

## <a name="errors-in-activity-functions"></a>Fel i Aktivitetsfunktioner

Alla undantag som genereras i en aktivitet funktionen ordnas tillbaka till orchestrator-funktion och genereras som en `FunctionFailedException`. Du kan skriva felhantering och kompensation felkoden som passar dina behov i orchestrator-funktion.

Anta exempelvis att följande orchestrator-funktion som överför pengar från ett konto till en annan:

### <a name="c"></a>C#

```csharp
#r "Microsoft.Azure.WebJobs.Extensions.DurableTask"

public static async Task Run(DurableOrchestrationContext context)
{
    var transferDetails = ctx.GetInput<TransferOperation>();

    await context.CallActivityAsync("DebitAccount",
        new
        {
            Account = transferDetails.SourceAccount,
            Amount = transferDetails.Amount
        });

    try
    {
        await context.CallActivityAsync("CreditAccount",
            new
            {
                Account = transferDetails.DestinationAccount,
                Amount = transferDetails.Amount
            });
    }
    catch (Exception)
    {
        // Refund the source account.
        // Another try/catch could be used here based on the needs of the application.
        await context.CallActivityAsync("CreditAccount",
            new
            {
                Account = transferDetails.SourceAccount,
                Amount = transferDetails.Amount
            });
    }
}
```

### <a name="javascript-functions-2x-only"></a>JavaScript (fungerar endast 2.x)

```javascript
const df = require("durable-functions");

module.exports = df.orchestrator(function*(context) {
    const transferDetails = context.df.getInput();

    yield context.df.callActivity("DebitAccount",
        {
            account = transferDetails.sourceAccount,
            amount = transferDetails.amount,
        }
    );

    try {
        yield context.df.callActivity("CreditAccount",
            {
                account = transferDetails.destinationAccount,
                amount = transferDetails.amount,
            }
        );
    }
    catch (error) {
        // Refund the source account.
        // Another try/catch could be used here based on the needs of the application.
        yield context.df.callActivity("CreditAccount",
            {
                account = transferDetails.sourceAccount,
                amount = transferDetails.amount,
            }
        );
    }
});
```

Om anropet till den **CreditAccount** misslyckas åtgärden för mål-konto, orchestrator-funktion kompenserar för det här genom kreditering pengar tillbaka till källkontot.

## <a name="automatic-retry-on-failure"></a>Automatiska återförsök vid fel

När du anropar Aktivitetsfunktioner eller underordnade orchestration-funktioner, kan du ange en automatisk återförsöksprincip. I följande exempel försöker anropa en funktion upp till tre gånger och väntar 5 sekunder mellan varje nytt försök:

### <a name="c"></a>C#

```csharp
public static async Task Run(DurableOrchestrationContext context)
{
    var retryOptions = new RetryOptions(
        firstRetryInterval: TimeSpan.FromSeconds(5),
        maxNumberOfAttempts: 3);

    await ctx.CallActivityWithRetryAsync("FlakyFunction", retryOptions, null);

    // ...
}
```

### <a name="javascript-functions-2x-only"></a>JavaScript (fungerar endast 2.x)

```javascript
const df = require("durable-functions");

module.exports = df.orchestrator(function*(context) {
    const retryOptions = new df.RetryOptions(5000, 3);

    yield context.df.callActivityWithRetry("FlakyFunction", retryOptions);

    // ...
});
```

Den `CallActivityWithRetryAsync` (.NET) eller `callActivityWithRetry` (JavaScript) API tar en `RetryOptions` parametern. Suborchestration anrop med hjälp av den `CallSubOrchestratorWithRetryAsync` (.NET) eller `callSubOrchestratorWithRetry` (JavaScript) API kan använda dessa samma principer för återförsök.

Det finns flera alternativ för att anpassa automatisk återförsöksprincipen. Dessa inkluderar:

* **Maxantal försök**: Det maximala antalet nya försök.
* **Första återförsöket**: Hur lång tid att vänta innan den första återförsök.
* **Backoff koefficienten**: Koefficienten används för att fastställa ökningstakt för backoff. Standardvärdet är 1.
* **Max återförsöksintervallet**: Längsta tid som ska förflyta mellan försöken.
* **Nya försök**: Längsta tid för gör ett nytt försök görs. Standardinställningen är att försöka igen på obestämd tid.
* **Hantera**: Du kan ange en användardefinierad motringning som avgör huruvida ett funktionsanrop ska göras.

## <a name="function-timeouts"></a>Funktionen tidsgränser

Du kanske vill lämna ett funktionsanrop inom en orchestrator-funktion om det tar för lång tid att slutföra. Det korrekta sättet att göra detta idag är genom att skapa en [varaktiga timer](durable-functions-timers.md) med `context.CreateTimer` (.NET) eller `context.df.createTimer` (JavaScript) tillsammans med `Task.WhenAny` (.NET) eller `context.df.Task.any` (JavaScript), som i följande exempel:

### <a name="c"></a>C#

```csharp
public static async Task<bool> Run(DurableOrchestrationContext context)
{
    TimeSpan timeout = TimeSpan.FromSeconds(30);
    DateTime deadline = context.CurrentUtcDateTime.Add(timeout);

    using (var cts = new CancellationTokenSource())
    {
        Task activityTask = context.CallActivityAsync("FlakyFunction");
        Task timeoutTask = context.CreateTimer(deadline, cts.Token);

        Task winner = await Task.WhenAny(activityTask, timeoutTask);
        if (winner == activityTask)
        {
            // success case
            cts.Cancel();
            return true;
        }
        else
        {
            // timeout case
            return false;
        }
    }
}
```

### <a name="javascript-functions-2x-only"></a>JavaScript (fungerar endast 2.x)

```javascript
const df = require("durable-functions");
const moment = require("moment");

module.exports = df.orchestrator(function*(context) {
    const deadline = moment.utc(context.df.currentUtcDateTime).add(30, "s");

    const activityTask = context.df.callActivity("FlakyFunction");
    const timeoutTask = context.df.createTimer(deadline.toDate());

    const winner = yield context.df.Task.any([activityTask, timeoutTask]);
    if (winner === activityTask) {
        // success case
        timeoutTask.cancel();
        return true;
    } else {
        // timeout case
        return false;
    }
});
```

> [!NOTE]
> Den här mekanismen avslutar inte faktiskt pågående aktivitetskörning av funktion. Det helt enkelt står orchestrator-funktion att ignorera resultatet och gå vidare. Mer information finns i den [Timers](durable-functions-timers.md#usage-for-timeout) dokumentation.

## <a name="unhandled-exceptions"></a>Ohanterade undantag

Om en orchestrator-funktion misslyckas med ett ohanterat undantag, loggas information om undantaget och instansen är klar med en `Failed` status.

## <a name="next-steps"></a>Nästa steg

> [!div class="nextstepaction"]
> [Lär dig att diagnostisera problem](durable-functions-diagnostics.md)
